<?xml version="1.0" encoding="UTF-8"?>
<testng-results skipped="0" failed="1" ignored="0" retried="3" total="4" passed="0">
  <reporter-output>
  </reporter-output>
  <suite name="Default suite" duration-ms="91976" started-at="2022-07-25T13:01:19 IST" finished-at="2022-07-25T13:02:51 IST">
    <groups>
    </groups>
    <test name="Default test" duration-ms="91976" started-at="2022-07-25T13:01:19 IST" finished-at="2022-07-25T13:02:51 IST">
      <class name="com.Vtiger.TCs.TC_01_CreateOrganizationTest">
        <test-method status="PASS" signature="connectToDatabase()[pri:0, instance:com.Vtiger.TCs.TC_01_CreateOrganizationTest@4a87761d]" name="connectToDatabase" is-config="true" duration-ms="37" started-at="2022-07-25T13:01:19 IST" finished-at="2022-07-25T13:01:19 IST">
          <reporter-output>
          </reporter-output>
        </test-method> <!-- connectToDatabase -->
        <test-method status="PASS" signature="lauchBrowser()[pri:0, instance:com.Vtiger.TCs.TC_01_CreateOrganizationTest@4a87761d]" name="lauchBrowser" is-config="true" duration-ms="9709" started-at="2022-07-25T13:01:21 IST" finished-at="2022-07-25T13:01:31 IST">
          <reporter-output>
          </reporter-output>
        </test-method> <!-- lauchBrowser -->
        <test-method status="PASS" signature="loginToApp()[pri:0, instance:com.Vtiger.TCs.TC_01_CreateOrganizationTest@4a87761d]" name="loginToApp" is-config="true" duration-ms="13868" started-at="2022-07-25T13:01:31 IST" finished-at="2022-07-25T13:01:44 IST">
          <reporter-output>
          </reporter-output>
        </test-method> <!-- loginToApp -->
        <test-method status="SKIP" signature="createOrg()[pri:1, instance:com.Vtiger.TCs.TC_01_CreateOrganizationTest@4a87761d]" name="createOrg" duration-ms="2377" retried="true" started-at="2022-07-25T13:01:44 IST" finished-at="2022-07-25T13:01:47 IST">
          <exception class="java.lang.AssertionError">
            <message>
              <![CDATA[expected [false] but found [true]]]>
            </message>
            <full-stacktrace>
              <![CDATA[java.lang.AssertionError: expected [false] but found [true]
at org.testng.Assert.fail(Assert.java:99)
at org.testng.Assert.failNotEquals(Assert.java:1037)
at org.testng.Assert.assertFalse(Assert.java:67)
at org.testng.Assert.assertFalse(Assert.java:77)
at com.Vtiger.TCs.TC_01_CreateOrganizationTest.createOrg(TC_01_CreateOrganizationTest.java:26)
at sun.reflect.NativeMethodAccessorImpl.invoke0(Native Method)
at sun.reflect.NativeMethodAccessorImpl.invoke(NativeMethodAccessorImpl.java:62)
at sun.reflect.DelegatingMethodAccessorImpl.invoke(DelegatingMethodAccessorImpl.java:43)
at java.lang.reflect.Method.invoke(Method.java:498)
at org.testng.internal.MethodInvocationHelper.invokeMethod(MethodInvocationHelper.java:132)
at org.testng.internal.TestInvoker.invokeMethod(TestInvoker.java:599)
at org.testng.internal.TestInvoker.invokeTestMethod(TestInvoker.java:174)
at org.testng.internal.MethodRunner.runInSequence(MethodRunner.java:46)
at org.testng.internal.TestInvoker$MethodInvocationAgent.invoke(TestInvoker.java:822)
at org.testng.internal.TestInvoker.invokeTestMethods(TestInvoker.java:147)
at org.testng.internal.TestMethodWorker.invokeTestMethods(TestMethodWorker.java:146)
at org.testng.internal.TestMethodWorker.run(TestMethodWorker.java:128)
at java.util.ArrayList.forEach(ArrayList.java:1257)
at org.testng.TestRunner.privateRun(TestRunner.java:764)
at org.testng.TestRunner.run(TestRunner.java:585)
at org.testng.SuiteRunner.runTest(SuiteRunner.java:384)
at org.testng.SuiteRunner.runSequentially(SuiteRunner.java:378)
at org.testng.SuiteRunner.privateRun(SuiteRunner.java:337)
at org.testng.SuiteRunner.run(SuiteRunner.java:286)
at org.testng.SuiteRunnerWorker.runSuite(SuiteRunnerWorker.java:53)
at org.testng.SuiteRunnerWorker.run(SuiteRunnerWorker.java:96)
at org.testng.TestNG.runSuitesSequentially(TestNG.java:1218)
at org.testng.TestNG.runSuitesLocally(TestNG.java:1140)
at org.testng.TestNG.runSuites(TestNG.java:1069)
at org.testng.TestNG.run(TestNG.java:1037)
at org.testng.remote.AbstractRemoteTestNG.run(AbstractRemoteTestNG.java:115)
at org.testng.remote.RemoteTestNG.initAndRun(RemoteTestNG.java:251)
at org.testng.remote.RemoteTestNG.main(RemoteTestNG.java:77)
]]>
            </full-stacktrace>
          </exception> <!-- java.lang.AssertionError -->
          <reporter-output>
          </reporter-output>
        </test-method> <!-- createOrg -->
        <test-method status="PASS" signature="logout()[pri:0, instance:com.Vtiger.TCs.TC_01_CreateOrganizationTest@4a87761d]" name="logout" is-config="true" duration-ms="7900" started-at="2022-07-25T13:01:47 IST" finished-at="2022-07-25T13:01:55 IST">
          <reporter-output>
          </reporter-output>
        </test-method> <!-- logout -->
        <test-method status="PASS" signature="loginToApp()[pri:0, instance:com.Vtiger.TCs.TC_01_CreateOrganizationTest@4a87761d]" name="loginToApp" is-config="true" duration-ms="8026" started-at="2022-07-25T13:01:55 IST" finished-at="2022-07-25T13:02:03 IST">
          <reporter-output>
          </reporter-output>
        </test-method> <!-- loginToApp -->
        <test-method status="SKIP" signature="createOrg()[pri:1, instance:com.Vtiger.TCs.TC_01_CreateOrganizationTest@4a87761d]" name="createOrg" duration-ms="1024" retried="true" started-at="2022-07-25T13:02:03 IST" finished-at="2022-07-25T13:02:04 IST">
          <exception class="java.lang.AssertionError">
            <message>
              <![CDATA[expected [false] but found [true]]]>
            </message>
            <full-stacktrace>
              <![CDATA[java.lang.AssertionError: expected [false] but found [true]
at org.testng.Assert.fail(Assert.java:99)
at org.testng.Assert.failNotEquals(Assert.java:1037)
at org.testng.Assert.assertFalse(Assert.java:67)
at org.testng.Assert.assertFalse(Assert.java:77)
at com.Vtiger.TCs.TC_01_CreateOrganizationTest.createOrg(TC_01_CreateOrganizationTest.java:26)
at sun.reflect.NativeMethodAccessorImpl.invoke0(Native Method)
at sun.reflect.NativeMethodAccessorImpl.invoke(NativeMethodAccessorImpl.java:62)
at sun.reflect.DelegatingMethodAccessorImpl.invoke(DelegatingMethodAccessorImpl.java:43)
at java.lang.reflect.Method.invoke(Method.java:498)
at org.testng.internal.MethodInvocationHelper.invokeMethod(MethodInvocationHelper.java:132)
at org.testng.internal.TestInvoker.invokeMethod(TestInvoker.java:599)
at org.testng.internal.TestInvoker.retryFailed(TestInvoker.java:214)
at org.testng.internal.MethodRunner.runInSequence(MethodRunner.java:58)
at org.testng.internal.TestInvoker$MethodInvocationAgent.invoke(TestInvoker.java:822)
at org.testng.internal.TestInvoker.invokeTestMethods(TestInvoker.java:147)
at org.testng.internal.TestMethodWorker.invokeTestMethods(TestMethodWorker.java:146)
at org.testng.internal.TestMethodWorker.run(TestMethodWorker.java:128)
at java.util.ArrayList.forEach(ArrayList.java:1257)
at org.testng.TestRunner.privateRun(TestRunner.java:764)
at org.testng.TestRunner.run(TestRunner.java:585)
at org.testng.SuiteRunner.runTest(SuiteRunner.java:384)
at org.testng.SuiteRunner.runSequentially(SuiteRunner.java:378)
at org.testng.SuiteRunner.privateRun(SuiteRunner.java:337)
at org.testng.SuiteRunner.run(SuiteRunner.java:286)
at org.testng.SuiteRunnerWorker.runSuite(SuiteRunnerWorker.java:53)
at org.testng.SuiteRunnerWorker.run(SuiteRunnerWorker.java:96)
at org.testng.TestNG.runSuitesSequentially(TestNG.java:1218)
at org.testng.TestNG.runSuitesLocally(TestNG.java:1140)
at org.testng.TestNG.runSuites(TestNG.java:1069)
at org.testng.TestNG.run(TestNG.java:1037)
at org.testng.remote.AbstractRemoteTestNG.run(AbstractRemoteTestNG.java:115)
at org.testng.remote.RemoteTestNG.initAndRun(RemoteTestNG.java:251)
at org.testng.remote.RemoteTestNG.main(RemoteTestNG.java:77)
]]>
            </full-stacktrace>
          </exception> <!-- java.lang.AssertionError -->
          <reporter-output>
          </reporter-output>
        </test-method> <!-- createOrg -->
        <test-method status="PASS" signature="logout()[pri:0, instance:com.Vtiger.TCs.TC_01_CreateOrganizationTest@4a87761d]" name="logout" is-config="true" duration-ms="10740" started-at="2022-07-25T13:02:04 IST" finished-at="2022-07-25T13:02:15 IST">
          <reporter-output>
          </reporter-output>
        </test-method> <!-- logout -->
        <test-method status="PASS" signature="loginToApp()[pri:0, instance:com.Vtiger.TCs.TC_01_CreateOrganizationTest@4a87761d]" name="loginToApp" is-config="true" duration-ms="8124" started-at="2022-07-25T13:02:15 IST" finished-at="2022-07-25T13:02:23 IST">
          <reporter-output>
          </reporter-output>
        </test-method> <!-- loginToApp -->
        <test-method status="SKIP" signature="createOrg()[pri:1, instance:com.Vtiger.TCs.TC_01_CreateOrganizationTest@4a87761d]" name="createOrg" duration-ms="540" retried="true" started-at="2022-07-25T13:02:23 IST" finished-at="2022-07-25T13:02:23 IST">
          <exception class="java.lang.AssertionError">
            <message>
              <![CDATA[expected [false] but found [true]]]>
            </message>
            <full-stacktrace>
              <![CDATA[java.lang.AssertionError: expected [false] but found [true]
at org.testng.Assert.fail(Assert.java:99)
at org.testng.Assert.failNotEquals(Assert.java:1037)
at org.testng.Assert.assertFalse(Assert.java:67)
at org.testng.Assert.assertFalse(Assert.java:77)
at com.Vtiger.TCs.TC_01_CreateOrganizationTest.createOrg(TC_01_CreateOrganizationTest.java:26)
at sun.reflect.NativeMethodAccessorImpl.invoke0(Native Method)
at sun.reflect.NativeMethodAccessorImpl.invoke(NativeMethodAccessorImpl.java:62)
at sun.reflect.DelegatingMethodAccessorImpl.invoke(DelegatingMethodAccessorImpl.java:43)
at java.lang.reflect.Method.invoke(Method.java:498)
at org.testng.internal.MethodInvocationHelper.invokeMethod(MethodInvocationHelper.java:132)
at org.testng.internal.TestInvoker.invokeMethod(TestInvoker.java:599)
at org.testng.internal.TestInvoker.retryFailed(TestInvoker.java:214)
at org.testng.internal.MethodRunner.runInSequence(MethodRunner.java:58)
at org.testng.internal.TestInvoker$MethodInvocationAgent.invoke(TestInvoker.java:822)
at org.testng.internal.TestInvoker.invokeTestMethods(TestInvoker.java:147)
at org.testng.internal.TestMethodWorker.invokeTestMethods(TestMethodWorker.java:146)
at org.testng.internal.TestMethodWorker.run(TestMethodWorker.java:128)
at java.util.ArrayList.forEach(ArrayList.java:1257)
at org.testng.TestRunner.privateRun(TestRunner.java:764)
at org.testng.TestRunner.run(TestRunner.java:585)
at org.testng.SuiteRunner.runTest(SuiteRunner.java:384)
at org.testng.SuiteRunner.runSequentially(SuiteRunner.java:378)
at org.testng.SuiteRunner.privateRun(SuiteRunner.java:337)
at org.testng.SuiteRunner.run(SuiteRunner.java:286)
at org.testng.SuiteRunnerWorker.runSuite(SuiteRunnerWorker.java:53)
at org.testng.SuiteRunnerWorker.run(SuiteRunnerWorker.java:96)
at org.testng.TestNG.runSuitesSequentially(TestNG.java:1218)
at org.testng.TestNG.runSuitesLocally(TestNG.java:1140)
at org.testng.TestNG.runSuites(TestNG.java:1069)
at org.testng.TestNG.run(TestNG.java:1037)
at org.testng.remote.AbstractRemoteTestNG.run(AbstractRemoteTestNG.java:115)
at org.testng.remote.RemoteTestNG.initAndRun(RemoteTestNG.java:251)
at org.testng.remote.RemoteTestNG.main(RemoteTestNG.java:77)
]]>
            </full-stacktrace>
          </exception> <!-- java.lang.AssertionError -->
          <reporter-output>
          </reporter-output>
        </test-method> <!-- createOrg -->
        <test-method status="PASS" signature="logout()[pri:0, instance:com.Vtiger.TCs.TC_01_CreateOrganizationTest@4a87761d]" name="logout" is-config="true" duration-ms="9309" started-at="2022-07-25T13:02:23 IST" finished-at="2022-07-25T13:02:33 IST">
          <reporter-output>
          </reporter-output>
        </test-method> <!-- logout -->
        <test-method status="PASS" signature="loginToApp()[pri:0, instance:com.Vtiger.TCs.TC_01_CreateOrganizationTest@4a87761d]" name="loginToApp" is-config="true" duration-ms="7693" started-at="2022-07-25T13:02:33 IST" finished-at="2022-07-25T13:02:40 IST">
          <reporter-output>
          </reporter-output>
        </test-method> <!-- loginToApp -->
        <test-method status="FAIL" signature="createOrg()[pri:1, instance:com.Vtiger.TCs.TC_01_CreateOrganizationTest@4a87761d]" name="createOrg" duration-ms="239" started-at="2022-07-25T13:02:40 IST" finished-at="2022-07-25T13:02:41 IST">
          <exception class="java.lang.AssertionError">
            <message>
              <![CDATA[expected [false] but found [true]]]>
            </message>
            <full-stacktrace>
              <![CDATA[java.lang.AssertionError: expected [false] but found [true]
at org.testng.Assert.fail(Assert.java:99)
at org.testng.Assert.failNotEquals(Assert.java:1037)
at org.testng.Assert.assertFalse(Assert.java:67)
at org.testng.Assert.assertFalse(Assert.java:77)
at com.Vtiger.TCs.TC_01_CreateOrganizationTest.createOrg(TC_01_CreateOrganizationTest.java:26)
at sun.reflect.NativeMethodAccessorImpl.invoke0(Native Method)
at sun.reflect.NativeMethodAccessorImpl.invoke(NativeMethodAccessorImpl.java:62)
at sun.reflect.DelegatingMethodAccessorImpl.invoke(DelegatingMethodAccessorImpl.java:43)
at java.lang.reflect.Method.invoke(Method.java:498)
at org.testng.internal.MethodInvocationHelper.invokeMethod(MethodInvocationHelper.java:132)
at org.testng.internal.TestInvoker.invokeMethod(TestInvoker.java:599)
at org.testng.internal.TestInvoker.retryFailed(TestInvoker.java:214)
at org.testng.internal.MethodRunner.runInSequence(MethodRunner.java:58)
at org.testng.internal.TestInvoker$MethodInvocationAgent.invoke(TestInvoker.java:822)
at org.testng.internal.TestInvoker.invokeTestMethods(TestInvoker.java:147)
at org.testng.internal.TestMethodWorker.invokeTestMethods(TestMethodWorker.java:146)
at org.testng.internal.TestMethodWorker.run(TestMethodWorker.java:128)
at java.util.ArrayList.forEach(ArrayList.java:1257)
at org.testng.TestRunner.privateRun(TestRunner.java:764)
at org.testng.TestRunner.run(TestRunner.java:585)
at org.testng.SuiteRunner.runTest(SuiteRunner.java:384)
at org.testng.SuiteRunner.runSequentially(SuiteRunner.java:378)
at org.testng.SuiteRunner.privateRun(SuiteRunner.java:337)
at org.testng.SuiteRunner.run(SuiteRunner.java:286)
at org.testng.SuiteRunnerWorker.runSuite(SuiteRunnerWorker.java:53)
at org.testng.SuiteRunnerWorker.run(SuiteRunnerWorker.java:96)
at org.testng.TestNG.runSuitesSequentially(TestNG.java:1218)
at org.testng.TestNG.runSuitesLocally(TestNG.java:1140)
at org.testng.TestNG.runSuites(TestNG.java:1069)
at org.testng.TestNG.run(TestNG.java:1037)
at org.testng.remote.AbstractRemoteTestNG.run(AbstractRemoteTestNG.java:115)
at org.testng.remote.RemoteTestNG.initAndRun(RemoteTestNG.java:251)
at org.testng.remote.RemoteTestNG.main(RemoteTestNG.java:77)
]]>
            </full-stacktrace>
          </exception> <!-- java.lang.AssertionError -->
          <reporter-output>
          </reporter-output>
        </test-method> <!-- createOrg -->
        <test-method status="PASS" signature="logout()[pri:0, instance:com.Vtiger.TCs.TC_01_CreateOrganizationTest@4a87761d]" name="logout" is-config="true" duration-ms="9360" started-at="2022-07-25T13:02:42 IST" finished-at="2022-07-25T13:02:51 IST">
          <reporter-output>
          </reporter-output>
        </test-method> <!-- logout -->
        <test-method status="PASS" signature="closebrowser()[pri:0, instance:com.Vtiger.TCs.TC_01_CreateOrganizationTest@4a87761d]" name="closebrowser" is-config="true" duration-ms="178" started-at="2022-07-25T13:02:51 IST" finished-at="2022-07-25T13:02:51 IST">
          <reporter-output>
          </reporter-output>
        </test-method> <!-- closebrowser -->
        <test-method status="PASS" signature="diconnectToDatabase()[pri:0, instance:com.Vtiger.TCs.TC_01_CreateOrganizationTest@4a87761d]" name="diconnectToDatabase" is-config="true" duration-ms="1" started-at="2022-07-25T13:02:53 IST" finished-at="2022-07-25T13:02:53 IST">
          <reporter-output>
          </reporter-output>
        </test-method> <!-- diconnectToDatabase -->
      </class> <!-- com.Vtiger.TCs.TC_01_CreateOrganizationTest -->
    </test> <!-- Default test -->
  </suite> <!-- Default suite -->
</testng-results>
